<?xml version='1.0'?>
<!-- x-green y-red z-blue - for all values - depending on where robot is facing - generally x-->
<robot name="amp_robot" xmlns:xacro="http://www.ros.org/wiki/xacro">

	<xacro:include filename="$(find amp_robot)/urdf/amp_robot.gazebo" />	
	<xacro:include filename="$(find amp_robot)/urdf/bumper.urdf.xacro" />		
	
	<link name="robot_footprint"></link>

	<joint name="robot_footprint_joint" type="fixed">
		<origin xyz="0 0 0" rpy="0 0 0" />
    <parent link="robot_footprint" />
    <child link="chassis" />
	</joint>

  <link name="chassis">
		<pose>0 0 0.1 0 0 0</pose>

		<inertial>
			<mass value="15.0" />
			<origin xyz="0.0 0 0" rpy="0 0 0"/>
			<inertia
				ixx="0.1" ixy="0" ixz="0"
				iyy="0.1"	iyz="0"
				izz="0.1"
			/>
		</inertial>

		<collision name="collision">
			<origin xyz="0.0 0 0" rpy="0 0 0"/>
			<geometry>
				<box size=".2 .15 .15"/> <!-- .2 .15 .07 -->
			</geometry>
		</collision>

		<visual name="chassis_visual">
			<origin xyz="0.0 0 0" rpy="0 0 0"/>
			<geometry>
				<box size=".2 .15 .15"/>
			</geometry>
		</visual>


		<collision name="back_caster_collision">
			<origin xyz="-0.06 0 -0.06" rpy="0 0 0"/><!-- -0.06 0 -0.02-->
			<geometry>
				<sphere radius="0.0299"/>
			</geometry>
		</collision>

		<visual name="back_caster_visual">
			<origin xyz="-0.06 0 -0.06" rpy="0 0 0"/>
			<geometry>
				<sphere radius="0.03"/>
			</geometry>
		</visual>


		<collision name="front_caster_collision">
			<origin xyz="0.06 0 -0.06" rpy="0 0 0"/>
			<geometry>
				<sphere radius="0.0299"/>
			</geometry>
		</collision>

		<visual name="front_caster_visual">
			<origin xyz="0.06 0 -0.06" rpy="0 0 0"/>
			<geometry>
				<sphere radius="0.03"/>
			</geometry>
		</visual>

	</link>

	<link name="left_wheel">
		<!-- <pose>0 0 0 0 0 0</pose> -->

		<inertial>
			<mass value="5.0" />
			<origin xyz="0 0 0" rpy="0 1.5707 1.5707"/>
			<inertia 
				ixx="0.1" ixy="0" ixz="0"
				iyy="0.1" iyz="0"
				izz="0.1"
			/>
		</inertial>

		<collision name="left_wheel_collision">
			<origin xyz="0 0 0" rpy="0 1.5707 1.5707"/>
			<geometry>
				<cylinder radius="0.0499" length="0.02499"/>
			</geometry>
		</collision>

		<visual name="left_wheel_visual">
			<origin xyz="0 0 0" rpy="0 1.5707 1.5707"/>
			<geometry>
				<cylinder radius="0.05" length="0.025"/>
			</geometry>
		</visual>

	</link>

	<link name="right_wheel">
		<!-- <pose>0 0 0 0 0 0</pose> -->

		<inertial>
			<mass value="5.0" />
			<origin xyz="0 0 0" rpy="0 1.5707 1.5707"/>
			<inertia 
				ixx="0.1" ixy="0" ixz="0"
				iyy="0.1" iyz="0"
				izz="0.1"
			/>
		</inertial>

		<collision name="right_wheel_collision">
			<origin xyz="0 0 0" rpy="0 1.5707 1.5707"/>
			<geometry>
				<cylinder radius="0.0499" length="0.02499"/>
			</geometry>
		</collision>

		<visual name="right_wheel_visual">
			<origin xyz="0 0 0" rpy="0 1.5707 1.5707"/>
			<geometry>
				<cylinder radius="0.05" length="0.025"/>
			</geometry>
		</visual>

	</link>

	<joint name="left_wheel_hinge" type="continuous">
		<origin xyz="0 0.088 -0.04" rpy="0 0 0"/>
		<child link="left_wheel"/>
		<parent link="chassis"/>
		<axis xyz="0 1 0" rpy="0 0 0"/>
		<limit effort="10000" velocity="1000"/>
		<dynamics damping="1.0" friction="1.0"/>
	</joint>

	<joint name="right_wheel_hinge" type="continuous">
		<origin xyz="0 -0.088 -0.04" rpy="0 0 0"/>
		<child link="right_wheel"/>
		<parent link="chassis"/>
		<axis xyz="0 1 0" rpy="0 0 0"/>
		<limit effort="10000" velocity="1000"/>
		<dynamics damping="1.0" friction="1.0"/>
	</joint>

	<xacro:macro name="base" params="name">
  	<xacro:bumper name="bumper" parent="chassis" ros_topic="bumper_state" update_rate="15.0" >
    	<origin xyz="0 0 0" rpy="0 0 0"/>
  	</xacro:bumper>
	</xacro:macro>
   
	
	<!--<joint name="bumper_joint" type="fixed">
		<origin xyz="0.08 0 0.04" rpy="0 0 0"/>
    <axis xyz="0 1 0" />
    <child link="bump_sensor"/> 
    <parent link="chassis"/>
	</joint>

	<link name="bump_sensor">
    <collision name = "bump_sensor_collision">
      <origin xyz="0 0 0" rpy="0 0 0"/>
      <geometry>
    		<box size="0.1 0.05 0.05"/>
      </geometry>
    </collision>

    <visual>
      <origin xyz="0 0 0" rpy="0 0 0"/>
      <geometry>
         <box size="0.1 0.05 0.05"/>
      </geometry>
    </visual>

    <inertial>
      <mass value="1e-5" />
      <origin xyz="0 0 0" rpy="0 0 0"/>
      <inertia ixx="1e-6" ixy="0" ixz="0" iyy="1e-6" iyz="0" izz="1e-6" />
    </inertial>
  </link>-->

	<gazebo reference="chassis">
    <material>Gazebo/Blue</material>
  </gazebo>

  <gazebo reference="left_wheel">
    <material>Gazebo/Black</material>
  </gazebo>

  <gazebo reference="right_wheel">
    <material>Gazebo/Black</material>
  </gazebo>

  <!--<gazebo reference="bump_sensor">
    <material>Gazebo/Red</material>
  </gazebo>-->

</robot>

						
